<!-- [TODO]: Make source spot movable using gripper -->
<mujoco model="gripper">
	<compiler angle="radian" inertiafromgeom="true"/>
	<default>
		<joint armature="1" damping="1" limited="true"/>
		<geom contype="0" friction="1 0.1 0.1" rgba="0.7 0.7 0 1"/>
	</default>
	<option gravity="0 0 -9.81" integrator="RK4" timestep="0.01"/>
	<worldbody>
		<!-- Arena -->
		<geom conaffinity="0" contype="0" name="ground" pos="0 0 0" rgba="0.9 0.9 0.9 1" size="1 1 10" type="plane"/>
		<geom conaffinity="0" fromto="-.35 -.35 .01 .35 -.35 .01" name="sideS" rgba="0.9 0.4 0.6 1" size=".02" type="capsule"/>
		<geom conaffinity="0" fromto=" .35 -.35 .01 .35  .35 .01" name="sideE" rgba="0.9 0.4 0.6 1" size=".02" type="capsule"/>
		<geom conaffinity="0" fromto="-.35  .35 .01 .35  .35 .01" name="sideN" rgba="0.9 0.4 0.6 1" size=".02" type="capsule"/>
		<geom conaffinity="0" fromto="-.35 -.35 .01 -.35 .35 .01" name="sideW" rgba="0.9 0.4 0.6 1" size=".02" type="capsule"/>
		<!-- Arm -->
		<geom conaffinity="0" contype="0" fromto="0 0 0 0 0 0.02" name="root" rgba="0.9 0.4 0.6 1" size=".011" type="cylinder"/>
		<body name="body0" pos="0 0 .01">
			<geom fromto="0 0 0 0.1 0 0" name="link0" rgba="0.0 0.4 0.6 1" size=".01" type="capsule"/>
			<joint axis="0 0 1" limited="false" name="joint0" pos="0 0 0" type="hinge"/>
			<body name="body1" pos="0.1 0 0">
				<joint axis="0 0 1" limited="true" name="joint1" pos="0 0 0" range="-3.0 3.0" type="hinge"/>
				<geom fromto="0 0 0 0.1 0 0" name="link1" rgba="0.0 0.4 0.6 1" size=".01" type="capsule"/>
				<body name="body2" pos="0.1 0 0">
					<joint axis="0 0 1" limited="true" name="joint2" pos="0 0 0" range="-3.0 3.0" type="hinge"/>
					<geom fromto="0 0 0 0.05 0 0" name="link2" rgba="0.0 0.4 0.6 1" size=".01" type="capsule"/>				
					<body name="gripper_left" pos="0.05 0 0">
						<joint axis="0 0 1" limited="true" name="joint_gripper_left" pos="0 0 0" range="-0.785 0" type="hinge"/>
						<geom contype="0" name="gripper_left_1" fromto="0 0 0 0 0.03 0" rgba="0.0 0.4 0.6 1" size=".01" type="capsule"/>
						<geom contype="0" name="gripper_left_2" fromto="0 0.03 0 0.03 0.03 0" rgba="0.0 0.4 0.6 1" size=".01" type="capsule"/>
					</body>
					<body name="gripper_right" pos="0.05 0 0">
						<joint axis="0 0 1" limited="true" name="joint_gripper_right" pos="0 0 0" range="0 0.785" type="hinge"/>
						<geom contype="0" name="gripper_right_1" fromto="0 0 0 0 -0.03 0" rgba="0.0 0.4 0.6 1" size=".01" type="capsule"/>
						<geom contype="0" name="gripper_right_2" fromto="0 -0.03 0 0.03 -0.03 0" rgba="0.0 0.4 0.6 1" size=".01" type="capsule"/>
					</body>
				</body>
			</body>
		</body>
		<!-- Source -->
		<body name="source_spot" pos=".1 -.1 .01">
			<joint armature="0" axis="1 0 0" damping="0" limited="true" name="source_x" pos="0 0 0" range="-.22 .22" ref=".1" stiffness="0" type="slide"/>
			<joint armature="0" axis="0 1 0" damping="0" limited="true" name="source_y" pos="0 0 0" range="-.22 .22" ref="-.1" stiffness="0" type="slide"/>
			<geom conaffinity="0" contype="0" name="source_spot" pos="0 0 0" rgba="0.3 0.96 0.26 1" size=".009" type="sphere"/>
		</body>
		<!-- Target -->
		<body name="target_spot" pos=".1 -.1 .01">
			<joint armature="0" axis="1 0 0" damping="0" limited="true" name="target_x" pos="0 0 0" range="-.32 .32" ref=".1" stiffness="0" type="slide"/>
			<joint armature="0" axis="0 1 0" damping="0" limited="true" name="target_y" pos="0 0 0" range="-.32 .32" ref="-.1" stiffness="0" type="slide"/>
			<geom conaffinity="0" contype="0" name="target_spot" pos="0 0 0" rgba="0.9 0.2 0.2 1" size=".009" type="sphere"/>
		</body>
	</worldbody>
	<actuator>
		<motor ctrllimited="true" ctrlrange="-1.0 1.0" gear="200.0" joint="joint0"/>
		<motor ctrllimited="true" ctrlrange="-1.0 1.0" gear="200.0" joint="joint1"/>
		<motor ctrllimited="true" ctrlrange="-1.0 1.0" gear="200.0" joint="joint2"/>
		<motor ctrllimited="true" ctrlrange="-0.75 0.75" gear="200.0" joint="joint_gripper_left"/>
		<motor ctrllimited="true" ctrlrange="-0.75 0.75" gear="200.0" joint="joint_gripper_right"/>
	</actuator>
</mujoco>